<?xml version="1.0" ?>
<!-- =================================================================================== -->
<!-- |    This document was autogenerated by xacro from rb1_arm.urdf.xacro             | -->
<!-- |    EDITING THIS FILE BY HAND IS NOT RECOMMENDED                                 | -->
<!-- =================================================================================== -->
<robot name="rb1_arm" xmlns:xacro="http://www.ros.org/wiki/xacro">
  <!-- ***************** -->
  <!-- Imported elements -->
  <!-- ***************** -->
  <!-- First we import all posible elements defined in the urdf.xacro files. All these elements are defined as macro:xacros -->
  <!-- Import RB1 arm elements -->
  <!-- Import all available sensors -->
  <!-- xacro:include filename="$(find rb1_arm_description)/urdf/sensors/all_sensors.urdf.xacro" / -->
  <!-- ***************** -->
  <!-- Global parameters -->
  <!-- ***************** -->
  <!-- Flag to select the high or low quality model -->
  <!-- RB-1 arm -->
  <xacro:property name="PI" value="3.1415926535897931"/>
  <xacro:property name="gearbox" value="500.0"/>
  <link name="base_link_rb1_arm">
    </link>
  <link name="link1_rb1_arm">
    <inertial>
      <mass value="1.0"/>
      <origin xyz="0 0 0"/>
      <inertia ixx="1.0" ixy="0.0" ixz="0.0" iyy="1.0" iyz="0.0" izz="1.0"/>
    </inertial>
    <visual>
      <origin rpy="0 0 0" xyz="0 0 0"/>
      <geometry>
        <mesh filename="package://rb1_arm_description/meshes/arms/armRB1_1_link.dae"/>
      </geometry>
      <material name="darkgrey">
        <color rgba="0.1 0.1 0.1 1"/>
      </material>
    </visual>
    <collision>
      <origin rpy="0 0 0 " xyz="0 0 0"/>
      <geometry>
        <mesh filename="package://rb1_arm_description/meshes/arms/armRB1_1_link.dae"/>
      </geometry>
    </collision>
  </link>
  <joint name="j1_rb1_arm" type="fixed">
    <origin rpy="0.0 0.0 0.0" xyz="0.0 0.0 0.0"/>
    <parent link="base_link_rb1_arm"/>
    <child link="link1_rb1_arm"/>
    <axis xyz="0 0 0"/>
  </joint>
  <link name="motor1_rb1_arm">
    <inertial>
      <mass value="1.0"/>
      <origin xyz="0 0 0"/>
      <inertia ixx="1.0" ixy="0.0" ixz="0.0" iyy="1.0" iyz="0.0" izz="1.0"/>
    </inertial>
    <visual>
      <origin rpy="0 0 0" xyz="0 0 0"/>
      <geometry>
        <mesh filename="package://rb1_arm_description/meshes/arms/armRB1_1_motor.dae"/>
      </geometry>
      <material name="darkgrey">
        <color rgba="0.1 0.1 0.1 1"/>
      </material>
    </visual>
    <collision>
      <origin rpy="0 0 0 " xyz="0 0 0"/>
      <geometry>
        <mesh filename="package://rb1_arm_description/meshes/arms/armRB1_1_motor.dae"/>
      </geometry>
    </collision>
  </link>
  <joint name="j1m_rb1_arm" type="fixed">
    <origin rpy="0.0 0.0 0.0" xyz="0.0 0.0 0.0"/>
    <parent link="link1_rb1_arm"/>
    <child link="motor1_rb1_arm"/>
    <axis xyz="0 0 0"/>
  </joint>
  <link name="link12_rb1_arm">
    <inertial>
      <mass value="1.0"/>
      <origin xyz="0 0 0"/>
      <inertia ixx="1.0" ixy="0.0" ixz="0.0" iyy="1.0" iyz="0.0" izz="1.0"/>
    </inertial>
    <visual>
      <origin rpy="0 0 0" xyz="0 0 0"/>
      <geometry>
        <mesh filename="package://rb1_arm_description/meshes/arms/armRB1_12_link.dae"/>
      </geometry>
      <material name="darkgrey">
        <color rgba="0.1 0.1 0.1 1"/>
      </material>
    </visual>
    <collision>
      <origin rpy="0 0 0 " xyz="0 0 0"/>
      <geometry>
        <mesh filename="package://rb1_arm_description/meshes/arms/armRB1_12_link.dae"/>
      </geometry>
    </collision>
  </link>
  <joint name="j12_rb1_arm" type="fixed">
    <origin rpy="0.0 0.0 0.0" xyz="0.0 0.0 0.0"/>
    <parent link="base_link_rb1_arm"/>
    <child link="link12_rb1_arm"/>
    <axis xyz="0 0 0"/>
  </joint>
  <link name="motor12_rb1_arm">
    <inertial>
      <mass value="1.0"/>
      <origin xyz="0 0 0"/>
      <inertia ixx="1.0" ixy="0.0" ixz="0.0" iyy="1.0" iyz="0.0" izz="1.0"/>
    </inertial>
    <visual>
      <origin rpy="0 0 0" xyz="0 0 0"/>
      <geometry>
        <mesh filename="package://rb1_arm_description/meshes/arms/armRB1_12_motor.dae"/>
      </geometry>
      <material name="darkgrey">
        <color rgba="0.1 0.1 0.1 1"/>
      </material>
    </visual>
    <collision>
      <origin rpy="0 0 0 " xyz="0 0 0"/>
      <geometry>
        <mesh filename="package://rb1_arm_description/meshes/arms/armRB1_12_motor.dae"/>
      </geometry>
    </collision>
  </link>
  <joint name="j12m_rb1_arm" type="fixed">
    <origin rpy="0.0 0.0 0.0" xyz="0.0 0.0 0.0"/>
    <parent link="link12_rb1_arm"/>
    <child link="motor12_rb1_arm"/>
    <axis xyz="0 0 0"/>
  </joint>
  <link name="link23_rb1_arm">
    <inertial>
      <mass value="1.0"/>
      <origin xyz="0 0 0"/>
      <inertia ixx="1.0" ixy="0.0" ixz="0.0" iyy="1.0" iyz="0.0" izz="1.0"/>
    </inertial>
    <visual>
      <origin rpy="0 0 0" xyz="0 0 0"/>
      <geometry>
        <mesh filename="package://rb1_arm_description/meshes/arms/armRB1_23_link.dae"/>
      </geometry>
      <material name="darkgrey">
        <color rgba="0.1 0.1 0.1 1"/>
      </material>
    </visual>
    <collision>
      <origin rpy="0 0 0 " xyz="0 0 0"/>
      <geometry>
        <mesh filename="package://rb1_arm_description/meshes/arms/armRB1_23_link.dae"/>
      </geometry>
    </collision>
  </link>
  <joint name="j23_rb1_arm" type="fixed">
    <origin rpy="0.0 0.0 0.0" xyz="0.0 0.0 0.0"/>
    <parent link="base_link_rb1_arm"/>
    <child link="link23_rb1_arm"/>
    <axis xyz="0 0 0"/>
  </joint>
  <link name="motor23_rb1_arm">
    <inertial>
      <mass value="1.0"/>
      <origin xyz="0 0 0"/>
      <inertia ixx="1.0" ixy="0.0" ixz="0.0" iyy="1.0" iyz="0.0" izz="1.0"/>
    </inertial>
    <visual>
      <origin rpy="0 0 0" xyz="0 0 0"/>
      <geometry>
        <mesh filename="package://rb1_arm_description/meshes/arms/armRB1_23_motor.dae"/>
      </geometry>
      <material name="darkgrey">
        <color rgba="0.1 0.1 0.1 1"/>
      </material>
    </visual>
    <collision>
      <origin rpy="0 0 0 " xyz="0 0 0"/>
      <geometry>
        <mesh filename="package://rb1_arm_description/meshes/arms/armRB1_23_motor.dae"/>
      </geometry>
    </collision>
  </link>
  <joint name="j23m_rb1_arm" type="fixed">
    <origin rpy="0.0 0.0 0.0" xyz="0.0 0.0 0.0"/>
    <parent link="link23_rb1_arm"/>
    <child link="motor23_rb1_arm"/>
    <axis xyz="0 0 0"/>
  </joint>
  <joint name="j1" type="revolute">
    <origin rpy="0.0 0.0 0.0" xyz="0 0 0.19178"/>
    <parent link="link1_rb1_arm"/>
    <child link="link12_rb1_arm"/>
    <axis xyz="0 0 -1"/>
    <limit effort="100.0" lower="-2.96706" upper="2.96706" velocity="3.0"/>
    <dynamics damping="0.5" friction="0.5"/>
  </joint>
  <transmission name="j1_trans">
    <type>transmission_interface/SimpleTransmission</type>
    <joint name="j1"/>
    <actuator name="j1_motor">
      <hardwareInterface>EffortJointInterface</hardwareInterface>
      <mechanicalReduction>500.0</mechanicalReduction>
      <motorTorqueConstant>5.0</motorTorqueConstant>
    </actuator>
  </transmission>
  <!-- Gazebo ros control plugins -->
  <gazebo>
    <plugin filename="libgazebo_ros_control.so" name="ros_control">
      <robotNamespace>/rb1_arm</robotNamespace>
      <robotParam>robot_description</robotParam>
      <controlPeriod>0.001</controlPeriod>
      <!-- controlPeriod>0.003</controlPeriod -->
      <robotSimType>gazebo_ros_control/DefaultRobotHWSim</robotSimType>
    </plugin>
  </gazebo>
</robot>

