<?xml version="1.0" ?>
<!-- =================================================================================== -->
<!-- |    This document was autogenerated by xacro from rb1_robot.urdf.xacro           | -->
<!-- |    EDITING THIS FILE BY HAND IS NOT RECOMMENDED                                 | -->
<!-- =================================================================================== -->
<robot name="rb1" xmlns:xacro="http://www.ros.org/wiki/xacro">
  <!-- ***************** -->
  <!-- Imported elements -->
  <!-- ***************** -->
  <!-- First we import all posible elements defined in the urdf.xacro files. All these elements are defined as macro:xacros -->
  <!-- Import RB1 base -->
  <gazebo reference="base_footprint">
    <material>Gazebo/Green</material>
  </gazebo>
  <xacro:rb1_base hq="true" name="rb1_base" publish_bf="true"/>
  <gazebo>
    <plugin filename="libgazebo_ros_control.so" name="ros_control">
      <robotNamespace>/rb1_arm</robotNamespace>
      <!-- robotNamespace>/rb1</robotNamespace -->
      <robotParam>robot_description</robotParam>
      <controlPeriod>0.001</controlPeriod>
      <!-- controlPeriod>0.003</controlPeriod -->
      <robotSimType>gazebo_ros_control/DefaultRobotHWSim</robotSimType>
    </plugin>
  </gazebo>
  <gazebo>
    <plugin filename="libgazebo_ros_diff_drive.so" name="differential_drive_controller">
      <alwaysOn>true</alwaysOn>
      <updateRate>50.0</updateRate>
      <!-- leftJoint>joint_left_wheel</leftJoint>
        <rightJoint>joint_right_wheel</rightJoint -->
      <leftJoint>joint_right_wheel</leftJoint>
      <rightJoint>joint_left_wheel</rightJoint>
      <wheelSeparation>0.365</wheelSeparation>
      <!-- wheelDiameter>0.1524</wheelDiameter -->
      <wheelDiameter>0.1524</wheelDiameter>
      <commandTopic>cmd_vel</commandTopic>
      <odometryTopic>odom</odometryTopic>
      <odometryFrame>odom</odometryFrame>
      <robotBaseFrame>base_footprint</robotBaseFrame>
      <!-- robotNamespace></robotNamespace -->
      <rosDebugLevel>na</rosDebugLevel>
      <publishWheelTF>false</publishWheelTF>
      <publishWheelJointState>false</publishWheelJointState>
      <wheelAcceleration>0</wheelAcceleration>
      <wheelTorque>5</wheelTorque>
      <!-- odometrySource>encoder</odometrySource -->
      <odometrySource>world</odometrySource>
      <publishTf>1</publishTf>
    </plugin>
  </gazebo>
  <joint name="joint_right_wheel" type="continuous">
    <parent link="base_link"/>
    <child link="right_wheel"/>
    <origin rpy="0 0 0" xyz="0.0 -0.183 0.051"/>
    <axis rpy="0 0 0" xyz="0 1 0"/>
    <limit effort="100" velocity="100"/>
    <joint_properties damping="0.0" friction="0.0"/>
  </joint>
  <link name="right_wheel">
    <visual>
      <!-- HIGH RESOLUTION WHEELS -->
      <origin rpy="0 0 0" xyz="0 0 0"/>
      <geometry>
        <mesh filename="package://rb1_base_description/meshes/wheels/wheel_rubber_6inch.dae"/>
      </geometry>
      <!-- LOW RESOLUTION WHEELS -->
    </visual>
    <collision>
      <origin rpy="1.57079632679 0 0" xyz="0 0 0"/>
      <geometry>
        <cylinder length="0.05" radius="0.076"/>
      </geometry>
    </collision>
    <inertial>
      <mass value="1.0"/>
      <origin xyz="0 0 0"/>
      <inertia ixx="0.00165233333333" ixy="0" ixz="0" iyy="0.00165233333333" iyz="0" izz="0.002888"/>
    </inertial>
  </link>
  <transmission name="right_wheel_joint_trans">
    <type>transmission_interface/SimpleTransmission</type>
    <joint name="joint_right_wheel"/>
    <actuator name="right_wheel_joint_motor">
      <hardwareInterface>EffortJointInterface</hardwareInterface>
      <mechanicalReduction>1</mechanicalReduction>
    </actuator>
  </transmission>
  <gazebo reference="right_wheel">
    <mu1 value="5.0"/>
    <mu2 value="0.5"/>
    <kp value="10000000.0"/>
    <kd value="1.0"/>
    <fdir1 value="1 0 0"/>
    <turnGravityOff>false</turnGravityOff>
  </gazebo>
  <joint name="joint_left_wheel" type="continuous">
    <parent link="base_link"/>
    <child link="left_wheel"/>
    <origin rpy="0 0 0" xyz="0.0 0.183 0.051"/>
    <axis rpy="0 0 0" xyz="0 1 0"/>
    <limit effort="100" velocity="100"/>
    <joint_properties damping="0.0" friction="0.0"/>
  </joint>
  <link name="left_wheel">
    <visual>
      <!-- HIGH RESOLUTION WHEELS -->
      <origin rpy="0 0 0" xyz="0 0 0"/>
      <geometry>
        <mesh filename="package://rb1_base_description/meshes/wheels/wheel_rubber_6inch.dae"/>
      </geometry>
      <!-- LOW RESOLUTION WHEELS -->
    </visual>
    <collision>
      <origin rpy="1.57079632679 0 0" xyz="0 0 0"/>
      <geometry>
        <cylinder length="0.05" radius="0.076"/>
      </geometry>
    </collision>
    <inertial>
      <mass value="1.0"/>
      <origin xyz="0 0 0"/>
      <inertia ixx="0.00165233333333" ixy="0" ixz="0" iyy="0.00165233333333" iyz="0" izz="0.002888"/>
    </inertial>
  </link>
  <transmission name="left_wheel_joint_trans">
    <type>transmission_interface/SimpleTransmission</type>
    <joint name="joint_left_wheel"/>
    <actuator name="left_wheel_joint_motor">
      <hardwareInterface>EffortJointInterface</hardwareInterface>
      <mechanicalReduction>1</mechanicalReduction>
    </actuator>
  </transmission>
  <gazebo reference="left_wheel">
    <mu1 value="5.0"/>
    <mu2 value="0.5"/>
    <kp value="10000000.0"/>
    <kd value="1.0"/>
    <fdir1 value="1 0 0"/>
    <turnGravityOff>false</turnGravityOff>
  </gazebo>
  <joint name="joint_omni_back_wheel" type="fixed">
    <parent link="base_link"/>
    <child link="omni_back_wheel"/>
    <origin rpy="0 0 0" xyz="-0.185 0.0 0.0265"/>
    <axis rpy="0 0 0" xyz="0 1 0"/>
    <limit effort="100" velocity="100"/>
    <joint_properties damping="0.0" friction="0.0"/>
  </joint>
  <link name="omni_back_wheel">
    <visual>
      <!-- HIGH RESOLUTION WHEELS -->
      <origin rpy="0 0 0" xyz="0 0 0"/>
      <geometry>
        <mesh filename="package://rb1_base_description/meshes/wheels/wheel_omni_4inch.dae"/>
      </geometry>
      <!-- LOW RESOLUTION WHEELS -->
    </visual>
    <!-- collision>
      <origin xyz="0 0 0" rpy="${M_PI/2} 0 0" />
        <geometry>
          <cylinder length="${omni_wheel_height}" radius="${omni_wheel_radius}" />
        </geometry>
      </collision -->
    <collision>
      <origin rpy="1.57079632679 0 0" xyz="0 0 0"/>
      <geometry>
        <sphere radius="0.051"/>
      </geometry>
    </collision>
    <inertial>
      <mass value="1.0"/>
      <origin xyz="0 0 0"/>
      <inertia ixx="0.0002107" ixy="0" ixz="0" iyy="0.0002107" iyz="0" izz="0.00039015"/>
      <!-- inertia  ixx="0.001" ixy="0.0"  ixz="0.0"  iyy="0.001"  iyz="0.0"  izz="0.001" / -->
    </inertial>
  </link>
  <gazebo reference="omni_back_wheel">
    <mu1 value="0.0"/>
    <mu2 value="0.0"/>
    <kp value="10000000.0"/>
    <kd value="1.0"/>
    <fdir1 value="1 0 0"/>
    <turnGravityOff>false</turnGravityOff>
  </gazebo>
  <joint name="joint_omni_front_left_wheel" type="fixed">
    <parent link="base_link"/>
    <child link="omni_front_left_wheel"/>
    <origin rpy="0 0 0" xyz="0.133 0.142 0.0265"/>
    <axis rpy="0 0 0" xyz="0 1 0"/>
    <limit effort="100" velocity="100"/>
    <joint_properties damping="0.0" friction="0.0"/>
  </joint>
  <link name="omni_front_left_wheel">
    <visual>
      <!-- HIGH RESOLUTION WHEELS -->
      <origin rpy="0 0 0" xyz="0 0 0"/>
      <geometry>
        <mesh filename="package://rb1_base_description/meshes/wheels/wheel_omni_4inch.dae"/>
      </geometry>
      <!-- LOW RESOLUTION WHEELS -->
    </visual>
    <!-- collision>
      <origin xyz="0 0 0" rpy="${M_PI/2} 0 0" />
        <geometry>
          <cylinder length="${omni_wheel_height}" radius="${omni_wheel_radius}" />
        </geometry>
      </collision -->
    <collision>
      <origin rpy="1.57079632679 0 0" xyz="0 0 0"/>
      <geometry>
        <sphere radius="0.051"/>
      </geometry>
    </collision>
    <inertial>
      <mass value="1.0"/>
      <origin xyz="0 0 0"/>
      <inertia ixx="0.0002107" ixy="0" ixz="0" iyy="0.0002107" iyz="0" izz="0.00039015"/>
      <!-- inertia  ixx="0.001" ixy="0.0"  ixz="0.0"  iyy="0.001"  iyz="0.0"  izz="0.001" / -->
    </inertial>
  </link>
  <gazebo reference="omni_front_left_wheel">
    <mu1 value="0.0"/>
    <mu2 value="0.0"/>
    <kp value="10000000.0"/>
    <kd value="1.0"/>
    <fdir1 value="1 0 0"/>
    <turnGravityOff>false</turnGravityOff>
  </gazebo>
  <joint name="joint_omni_front_right_wheel" type="fixed">
    <parent link="base_link"/>
    <child link="omni_front_right_wheel"/>
    <origin rpy="0 0 0" xyz="0.133 -0.142 0.0265"/>
    <axis rpy="0 0 0" xyz="0 1 0"/>
    <limit effort="100" velocity="100"/>
    <joint_properties damping="0.0" friction="0.0"/>
  </joint>
  <link name="omni_front_right_wheel">
    <visual>
      <!-- HIGH RESOLUTION WHEELS -->
      <origin rpy="0 0 0" xyz="0 0 0"/>
      <geometry>
        <mesh filename="package://rb1_base_description/meshes/wheels/wheel_omni_4inch.dae"/>
      </geometry>
      <!-- LOW RESOLUTION WHEELS -->
    </visual>
    <!-- collision>
      <origin xyz="0 0 0" rpy="${M_PI/2} 0 0" />
        <geometry>
          <cylinder length="${omni_wheel_height}" radius="${omni_wheel_radius}" />
        </geometry>
      </collision -->
    <collision>
      <origin rpy="1.57079632679 0 0" xyz="0 0 0"/>
      <geometry>
        <sphere radius="0.051"/>
      </geometry>
    </collision>
    <inertial>
      <mass value="1.0"/>
      <origin xyz="0 0 0"/>
      <inertia ixx="0.0002107" ixy="0" ixz="0" iyy="0.0002107" iyz="0" izz="0.00039015"/>
      <!-- inertia  ixx="0.001" ixy="0.0"  ixz="0.0"  iyy="0.001"  iyz="0.0"  izz="0.001" / -->
    </inertial>
  </link>
  <gazebo reference="omni_front_right_wheel">
    <mu1 value="0.0"/>
    <mu2 value="0.0"/>
    <kp value="10000000.0"/>
    <kd value="1.0"/>
    <fdir1 value="1 0 0"/>
    <turnGravityOff>false</turnGravityOff>
  </gazebo>
  <joint name="hokuyo_laser_joint" type="fixed">
    <!-- FRONT MOUNT  -->
    <!-- origin xyz="0.29 0 0.1" -->
    <!-- TOP MOUNT -->
    <!-- origin xyz="0.0 0.0 0.325"-->
    <origin rpy="0 0 0" xyz="0.210 0.0 0.305"/>
    <parent link="base_link"/>
    <child link="hokuyo_laser_link"/>
  </joint>
  <link name="hokuyo_laser_link">
    <collision>
      <origin rpy="0 0 0" xyz="0 0 0"/>
      <geometry>
        <box size="0.1 0.1 0.08"/>
      </geometry>
    </collision>
    <visual>
      <origin rpy="0 0 0" xyz="0 0 0"/>
      <geometry>
        <mesh filename="package://rb1_base_description/meshes/sensors/hokuyo_utm_30lx.dae"/>
      </geometry>
    </visual>
    <inertial>
      <mass value="1e-5"/>
      <origin rpy="0 0 0" xyz="0 0 0"/>
      <inertia ixx="1e-6" ixy="0" ixz="0" iyy="1e-6" iyz="0" izz="1e-6"/>
    </inertial>
  </link>
  <gazebo reference="hokuyo_laser_link">
    <sensor name="hokuyo_sensor" type="ray">
      <pose>0 0 0 0 0 0</pose>
      <visualize>false</visualize>
      <update_rate>30</update_rate>
      <ray>
        <scan>
          <horizontal>
            <samples>1081</samples>
            <resolution>1</resolution>
            <min_angle>2.35619449</min_angle>
            <!-- +/-135 deg -->
            <max_angle>-2.35619449</max_angle>
          </horizontal>
        </scan>
        <range>
          <min>0.10</min>
          <max>30.0</max>
          <resolution>0.01</resolution>
        </range>
        <noise>
          <type>gaussian</type>
          <mean>0.0</mean>
          <stddev>0.01</stddev>
        </noise>
      </ray>
      <plugin filename="libgazebo_ros_laser.so" name="gazebo_ros_head_hokuyo_controller">
        <topicName>hokuyo/scan</topicName>
        <frameName>hokuyo_laser_link</frameName>
      </plugin>
    </sensor>
  </gazebo>
  <joint name="hokuyo1_laser_joint" type="fixed">
    <origin rpy="0 3.1416 3.1416" xyz="0.220 0.0 0.170"/>
    <parent link="base_link"/>
    <child link="hokuyo1_laser_link"/>
  </joint>
  <link name="hokuyo1_laser_link">
    <collision>
      <origin rpy="0 0 0" xyz="0 0 -0.05"/>
      <geometry>
        <box size="0.1 0.1 0.08"/>
      </geometry>
    </collision>
    <visual>
      <origin rpy="0 0 0" xyz="0 0 -0.05"/>
      <geometry>
        <mesh filename="package://rb1_base_description/meshes/sensors/hokuyo_urg_04lx.dae"/>
      </geometry>
    </visual>
    <inertial>
      <mass value="1e-5"/>
      <origin rpy="0 0 0" xyz="0 0 0"/>
      <inertia ixx="1e-6" ixy="0" ixz="0" iyy="1e-6" iyz="0" izz="1e-6"/>
    </inertial>
  </link>
  <gazebo reference="hokuyo1_laser_link">
    <sensor name="hokuyo1_sensor" type="ray">
      <pose>0 0 0 0 0 0</pose>
      <visualize>false</visualize>
      <update_rate>30</update_rate>
      <ray>
        <scan>
          <horizontal>
            <samples>1081</samples>
            <resolution>1</resolution>
            <min_angle>2.35619449</min_angle>
            <!-- +/-135 deg -->
            <max_angle>-2.35619449</max_angle>
          </horizontal>
        </scan>
        <range>
          <min>0.10</min>
          <max>30.0</max>
          <resolution>0.01</resolution>
        </range>
        <noise>
          <type>gaussian</type>
          <mean>0.0</mean>
          <stddev>0.01</stddev>
        </noise>
      </ray>
      <plugin filename="libgazebo_ros_laser.so" name="gazebo_ros_head_hokuyo_controller">
        <topicName>hokuyo1/scan</topicName>
        <frameName>hokuyo1_laser_link</frameName>
      </plugin>
    </sensor>
  </gazebo>
  <joint name="imu_joint" type="fixed">
    <axis xyz="1 0 0"/>
    <!--origin xyz="0 0 0.2825"/-->
    <origin rpy="0 0 0" xyz="-0.18 0.0 0.170"/>
    <parent link="base_link"/>
    <child link="imu_link"/>
  </joint>
  <link name="imu_link">
    <inertial>
      <mass value="0.001"/>
      <origin rpy="0 0 0" xyz="0 0 0"/>
      <inertia ixx="0.0001" ixy="0" ixz="0" iyy="0.000001" iyz="0" izz="0.0001"/>
    </inertial>
    <visual>
      <origin rpy="0 0 0" xyz="0 0 0"/>
      <geometry>
        <box size="0.001 0.001 0.001"/>
      </geometry>
    </visual>
    <collision>
      <origin rpy="0 0 0" xyz="0 0 0"/>
      <geometry>
        <box size=".001 .001 .001"/>
      </geometry>
    </collision>
  </link>
  <gazebo>
    <plugin filename="libgazebo_ros_imu.so" name="ros_imu">
      <topicName>imu_data</topicName>
      <bodyName>imu_link</bodyName>
      <serviceName>imu_service</serviceName>
      <gaussianNoise>0.005</gaussianNoise>
    </plugin>
  </gazebo>
  <!-- Import RB1 torso -->
  <xacro:property name="PI" value="3.1415926535897931"/>
  <link name="base_link_rb1_torso">
  </link>
  <link name="link1_torso">
    <inertial>
      <mass value="3.0"/>
      <origin xyz="0 0 0"/>
      <inertia ixx="1.0" ixy="0.0" ixz="0.0" iyy="1.0" iyz="0.0" izz="1.0"/>
    </inertial>
    <visual>
      <origin rpy="0 0 0" xyz="0 0 0"/>
      <geometry>
        <mesh filename="package://rb1_torso_description/meshes/torsos/rb1_lower.dae"/>
      </geometry>
      <material name="darkgrey">
        <color rgba="0.1 0.1 0.1 1"/>
      </material>
    </visual>
    <collision>
      <origin rpy="0 0 0 " xyz="0 0 0"/>
      <geometry>
        <mesh filename="package://rb1_torso_description/meshes/torsos/rb1_lower.dae"/>
      </geometry>
    </collision>
  </link>
  <joint name="j0_rb1_torso" type="fixed">
    <origin rpy="0.0 0.0 0.0" xyz="0.0 0.0 0.0"/>
    <parent link="base_link_rb1_torso"/>
    <child link="link1_torso"/>
    <axis xyz="0 0 0"/>
  </joint>
  <link name="link2_torso">
    <inertial>
      <mass value="2.0"/>
      <origin xyz="0 0 0"/>
      <inertia ixx="1.0" ixy="0.0" ixz="0.0" iyy="1.0" iyz="0.0" izz="1.0"/>
    </inertial>
    <visual>
      <origin rpy="0 0 0" xyz="0 0 0"/>
      <geometry>
        <mesh filename="package://rb1_torso_description/meshes/torsos/rb1_upper.dae"/>
      </geometry>
      <material name="darkgrey">
        <color rgba="0.1 0.1 0.1 1"/>
      </material>
    </visual>
    <collision>
      <origin rpy="0 0 0 " xyz="0 0 0"/>
      <geometry>
        <mesh filename="package://rb1_torso_description/meshes/torsos/rb1_upper.dae"/>
      </geometry>
    </collision>
  </link>
  <joint name="j1_torso" type="prismatic">
    <origin rpy="0.0 0.0 0.0" xyz="0 0 0"/>
    <parent link="link1_torso"/>
    <child link="link2_torso"/>
    <axis xyz="0 0 1"/>
    <limit effort="2500.0" lower="0.0" upper="0.36" velocity="3.0"/>
    <dynamics damping="0.1" friction="0.1"/>
  </joint>
  <transmission name="j1_torso_trans">
    <type>transmission_interface/SimpleTransmission</type>
    <joint name="j1_torso"/>
    <actuator name="j1_torso_motor">
      <hardwareInterface>EffortJointInterface</hardwareInterface>
      <mechanicalReduction>320.0</mechanicalReduction>
      <motorTorqueConstant>1.0</motorTorqueConstant>
    </actuator>
  </transmission>
  <link name="link1_head">
    <inertial>
      <mass value="1.0"/>
      <origin xyz="0 0 0"/>
      <inertia ixx="1.0" ixy="0.0" ixz="0.0" iyy="1.0" iyz="0.0" izz="1.0"/>
    </inertial>
    <visual>
      <origin rpy="0 0 0" xyz="0 0 0"/>
      <geometry>
        <mesh filename="package://rb1_torso_description/meshes/heads/head1.dae"/>
      </geometry>
      <material name="darkgrey">
        <color rgba="0.1 0.1 0.1 1"/>
      </material>
    </visual>
    <collision>
      <origin rpy="0 0 0 " xyz="0 0 0"/>
      <geometry>
        <mesh filename="package://rb1_torso_description/meshes/heads/head1.dae"/>
      </geometry>
    </collision>
  </link>
  <joint name="j1_head" type="revolute">
    <origin rpy="0.0 0.0 0.0" xyz="0.010 0.0 0.940"/>
    <parent link="link2_torso"/>
    <child link="link1_head"/>
    <axis xyz="0 0 1"/>
    <limit effort="2500.0" lower="-1.57079632679" upper="1.57079632679" velocity="3.0"/>
    <dynamics damping="0.1" friction="0.1"/>
  </joint>
  <transmission name="j1_head_trans">
    <type>transmission_interface/SimpleTransmission</type>
    <joint name="j1_head"/>
    <actuator name="j1_head_motor">
      <hardwareInterface>EffortJointInterface</hardwareInterface>
      <mechanicalReduction>320.0</mechanicalReduction>
      <motorTorqueConstant>1.0</motorTorqueConstant>
    </actuator>
  </transmission>
  <link name="link2_head">
    <inertial>
      <mass value="1.0"/>
      <origin xyz="0 0 0"/>
      <inertia ixx="1.0" ixy="0.0" ixz="0.0" iyy="1.0" iyz="0.0" izz="1.0"/>
    </inertial>
    <visual>
      <origin rpy="0 0 0" xyz="0 0 0"/>
      <geometry>
        <mesh filename="package://rb1_torso_description/meshes/heads/head2.dae"/>
      </geometry>
      <material name="darkgrey">
        <color rgba="0.1 0.1 0.1 1"/>
      </material>
    </visual>
    <collision>
      <origin rpy="0 0 0 " xyz="0 0 0"/>
      <geometry>
        <mesh filename="package://rb1_torso_description/meshes/heads/head2.dae"/>
      </geometry>
    </collision>
  </link>
  <joint name="j2_head" type="revolute">
    <origin rpy="0.0 0.0 0.0" xyz="0.105 0.0 0.0"/>
    <parent link="link1_head"/>
    <child link="link2_head"/>
    <axis xyz="0 1 0"/>
    <limit effort="2500.0" lower="-0.785398163397" upper="0.785398163397" velocity="3.0"/>
    <dynamics damping="0.1" friction="0.1"/>
  </joint>
  <transmission name="j2_head_trans">
    <type>transmission_interface/SimpleTransmission</type>
    <joint name="j2_head"/>
    <actuator name="j2_head_motor">
      <hardwareInterface>EffortJointInterface</hardwareInterface>
      <mechanicalReduction>320.0</mechanicalReduction>
      <motorTorqueConstant>1.0</motorTorqueConstant>
    </actuator>
  </transmission>
  <joint name="xtion_head_cam_rgb_joint" type="fixed">
    <origin rpy="0 0 0" xyz="0.055 0.000 0.028"/>
    <parent link="link2_head"/>
    <child link="xtion_head_cam_rgb_frame"/>
  </joint>
  <link name="xtion_head_cam_rgb_frame">
    <inertial>
      <mass value="0.001"/>
      <origin xyz="0 0 0"/>
      <inertia ixx="0.0001" ixy="0.0" ixz="0.0" iyy="0.0001" iyz="0.0" izz="0.0001"/>
    </inertial>
  </link>
  <joint name="xtion_head_cam_rgb_optical_joint" type="fixed">
    <origin rpy="-1.57079632679 0 -1.57079632679" xyz="0 0 0"/>
    <parent link="xtion_head_cam_rgb_frame"/>
    <child link="xtion_head_cam_rgb_optical_frame"/>
  </joint>
  <link name="xtion_head_cam_rgb_optical_frame">
    <inertial>
      <mass value="0.001"/>
      <origin xyz="0 0 0"/>
      <inertia ixx="0.0001" ixy="0.0" ixz="0.0" iyy="0.0001" iyz="0.0" izz="0.0001"/>
    </inertial>
  </link>
  <joint name="xtion_head_cam_joint" type="fixed">
    <origin rpy="0 0 0" xyz="0 -0.022 0"/>
    <parent link="xtion_head_cam_rgb_frame"/>
    <child link="xtion_head_cam_link"/>
  </joint>
  <link name="xtion_head_cam_link">
    <visual>
      <origin rpy="-1.57079632679 -3.14159265359 -1.57079632679" xyz="-0.01 0 0"/>
      <geometry>
        <mesh filename="package://rb1_base_description/meshes/sensors/asus_xtion_pro_live.dae" scale="0.001 0.001 0.001"/>
      </geometry>
    </visual>
    <collision>
      <origin rpy="0 0 0" xyz="0.0 0.0 0.0"/>
      <geometry>
        <box size="0.0730 .2760 0.0720"/>
      </geometry>
    </collision>
    <inertial>
      <mass value="0.01"/>
      <origin xyz="0 0 0"/>
      <inertia ixx="0.001" ixy="0.0" ixz="0.0" iyy="0.001" iyz="0.0" izz="0.001"/>
    </inertial>
  </link>
  <joint name="xtion_head_cam_depth_joint" type="fixed">
    <origin rpy="0 0 0" xyz="0 0.027 0"/>
    <parent link="xtion_head_cam_rgb_frame"/>
    <child link="xtion_head_cam_depth_frame"/>
  </joint>
  <link name="xtion_head_cam_depth_frame">
    <inertial>
      <mass value="0.01"/>
      <origin xyz="0 0 0"/>
      <inertia ixx="0.001" ixy="0.0" ixz="0.0" iyy="0.001" iyz="0.0" izz="0.001"/>
    </inertial>
  </link>
  <joint name="xtion_head_cam_depth_optical_joint" type="fixed">
    <origin rpy="-1.57079632679 0 -1.57079632679" xyz="0 0 0"/>
    <parent link="xtion_head_cam_depth_frame"/>
    <child link="xtion_head_cam_depth_optical_frame"/>
  </joint>
  <link name="xtion_head_cam_depth_optical_frame">
    <inertial>
      <mass value="0.001"/>
      <origin xyz="0 0 0"/>
      <inertia ixx="0.0001" ixy="0.0" ixz="0.0" iyy="0.0001" iyz="0.0" izz="0.0001"/>
    </inertial>
  </link>
  <gazebo reference="xtion_head_cam_depth_frame">
    <sensor name="cam" type="depth">
      <always_on>true</always_on>
      <update_rate>20.0</update_rate>
      <camera>
        <horizontal_fov>1.0471975512</horizontal_fov>
        <image>
          <format>R8G8B8</format>
          <width>640</width>
          <height>480</height>
        </image>
        <clip>
          <near>0.05</near>
          <far>3.5</far>
        </clip>
      </camera>
      <plugin filename="libgazebo_ros_openni_kinect.so" name="xtion_pro_cam_controller">
        <cameraName>xtion_head</cameraName>
        <alwaysOn>true</alwaysOn>
        <updateRate>15</updateRate>
        <imageTopicName>rgb/image_raw</imageTopicName>
        <depthImageTopicName>depth/image_raw</depthImageTopicName>
        <pointCloudTopicName>depth/points</pointCloudTopicName>
        <cameraInfoTopicName>rgb/camera_info</cameraInfoTopicName>
        <depthImageCameraInfoTopicName>depth/camera_info</depthImageCameraInfoTopicName>
        <frameName>xtion_head_cam_depth_optical_frame</frameName>
        <baseline>0.1</baseline>
        <distortion_k1>0.0</distortion_k1>
        <distortion_k2>0.0</distortion_k2>
        <distortion_k3>0.0</distortion_k3>
        <distortion_t1>0.0</distortion_t1>
        <distortion_t2>0.0</distortion_t2>
        <pointCloudCutoff>0.4</pointCloudCutoff>
      </plugin>
    </sensor>
  </gazebo>
  <gazebo>
    <plugin filename="libgazebo_ros_control.so" name="ros_control">
      <robotNamespace>/rb1_arm</robotNamespace>
      <!-- robotNamespace>/rb1</robotNamespace -->
      <robotParam>robot_description</robotParam>
      <controlPeriod>0.001</controlPeriod>
      <!-- controlPeriod>0.003</controlPeriod -->
      <robotSimType>gazebo_ros_control/DefaultRobotHWSim</robotSimType>
    </plugin>
  </gazebo>
  <!-- Import RB1 arm -->
  <gazebo>
    <plugin filename="libgazebo_ros_control.so" name="ros_control">
      <robotNamespace>/rb1_gripper</robotNamespace>
      <controlPeriod>0.002</controlPeriod>
      <robotSimType>gazebo_ros_control/DefaultRobotHWSim</robotSimType>
    </plugin>
  </gazebo>
  <gazebo reference="base_link_gripper">
    <material>Gazebo/Grey</material>
  </gazebo>
  <gazebo reference="link_finger1">
    <material>Gazebo/Black</material>
  </gazebo>
  <gazebo reference="link_finger2">
    <material>Gazebo/Black</material>
  </gazebo>
  <link name="base_link_gripper">
    <inertial>
      <origin rpy="0 0 0" xyz="0.0 0.0 0.0"/>
      <mass value="0.2735"/>
      <inertia ixx="0.2735" ixy="0.0" ixz="0.0" iyy="0.2735" iyz="0.0" izz="0.2735"/>
    </inertial>
    <visual>
      <origin rpy="0 0 0" xyz="0 0 0"/>
      <geometry>
        <mesh filename="package://rb1_arm_description/meshes/grippers/base_gripper.dae"/>
      </geometry>
      <material name="">
        <color rgba="0.79216 0.81961 0.93333 1"/>
      </material>
    </visual>
    <collision>
      <origin rpy="0 0 0" xyz="0 0 0"/>
      <geometry>
        <mesh filename="package://rb1_arm_description/meshes/grippers/base_gripper.dae"/>
      </geometry>
      <contact_coefficients kd="1.0" kp="1000.0" mu="0"/>
    </collision>
  </link>
  <link name="link_finger1">
    <inertial>
      <origin rpy="0 0 0" xyz="0.0 0.0 0.0"/>
      <mass value="0.03"/>
      <inertia ixx="0.03" ixy="0.0" ixz="0.0" iyy="0.03" iyz="0.0" izz="0.03"/>
    </inertial>
    <visual>
      <origin rpy="0 0 0" xyz="0 0 0"/>
      <geometry>
        <mesh filename="package://rb1_arm_description/meshes/grippers/finger1.dae"/>
      </geometry>
      <material name="">
        <color rgba="0.792156862745098 0.819607843137255 0.933333333333333 1"/>
      </material>
    </visual>
    <collision>
      <origin rpy="0 0 0" xyz="0 0 0"/>
      <geometry>
        <mesh filename="package://rb1_arm_description/meshes/grippers/finger1.dae"/>
      </geometry>
    </collision>
  </link>
  <joint name="jg1" type="revolute">
    <origin rpy="3.0028E-16 5.9154E-22 2.2204E-16" xyz="0.097993 0.028575 0"/>
    <parent link="base_link_gripper"/>
    <child link="link_finger1"/>
    <axis xyz="0 0 -1"/>
    <limit effort="2500.0" lower="-1.0" upper="1.0" velocity="3.0"/>
    <dynamics damping="0.1" friction="0.1"/>
  </joint>
  <transmission name="jg1_trans">
    <type>transmission_interface/SimpleTransmission</type>
    <joint name="jg1"/>
    <actuator name="jg1_motor">
      <hardwareInterface>EffortJointInterface</hardwareInterface>
      <mechanicalReduction>304.0</mechanicalReduction>
      <motorTorqueConstant>3.0</motorTorqueConstant>
    </actuator>
  </transmission>
  <link name="link_finger2">
    <inertial>
      <origin rpy="0 0 0" xyz="0.0 0.0 0.0"/>
      <mass value="0.03"/>
      <inertia ixx="0.03" ixy="0.0" ixz="0.0" iyy="0.03" iyz="0.0" izz="0.03"/>
    </inertial>
    <visual>
      <origin rpy="0 0 0" xyz="0 0 0"/>
      <geometry>
        <mesh filename="package://rb1_arm_description/meshes/grippers/finger2.dae"/>
      </geometry>
      <material name="">
        <color rgba="0.792156862745098 0.819607843137255 0.933333333333333 1"/>
      </material>
    </visual>
    <collision>
      <origin rpy="0 0 0" xyz="0 0 0"/>
      <geometry>
        <mesh filename="package://rb1_arm_description/meshes/grippers/finger2.dae"/>
      </geometry>
    </collision>
  </link>
  <joint name="jg2" type="revolute">
    <origin rpy="3.0028E-16 7.477E-22 -5.1764E-15" xyz="0.097993 -0.028575 0"/>
    <parent link="base_link_gripper"/>
    <child link="link_finger2"/>
    <axis xyz="0 0 -1"/>
    <limit effort="2500.0" lower="-1.0" upper="1.0" velocity="3.0"/>
    <dynamics damping="0.1" friction="0.1"/>
  </joint>
  <transmission name="jg2_trans">
    <type>transmission_interface/SimpleTransmission</type>
    <joint name="jg2"/>
    <actuator name="jg2_motor">
      <hardwareInterface>EffortJointInterface</hardwareInterface>
      <mechanicalReduction>304.0</mechanicalReduction>
      <motorTorqueConstant>3.0</motorTorqueConstant>
    </actuator>
  </transmission>
  <joint name="gripper_joint" type="fixed">
    <origin rpy="0.0 -1.57079632679 0.0" xyz="0.0 0.0 0.0"/>
    <parent link="end_effector_rb1_arm"/>
    <child link="base_link_gripper"/>
    <axis xyz="0 0 1"/>
  </joint>
  <xacro:property name="PI" value="3.1415926535897931"/>
  <link name="base_link_rb1_arm">
    </link>
  <link name="link1_rb1_arm">
    <inertial>
      <mass value="0.5"/>
      <origin xyz="0 0 0"/>
      <inertia ixx="0.01" ixy="0.0" ixz="0.0" iyy="0.01" iyz="0.0" izz="0.01"/>
    </inertial>
    <visual>
      <origin rpy="0 0 0" xyz="0 0 0"/>
      <geometry>
        <mesh filename="package://rb1_arm_description/meshes/arms/armRB1_1_link.dae"/>
      </geometry>
      <material name="darkgrey">
        <color rgba="0.1 0.1 0.1 1"/>
      </material>
    </visual>
    <collision>
      <origin rpy="0 0 0 " xyz="0 0 0"/>
      <geometry>
        <mesh filename="package://rb1_arm_description/meshes/arms/armRB1_1_link.dae"/>
      </geometry>
    </collision>
  </link>
  <link name="motor1_rb1_arm">
    <inertial>
      <mass value="0.5"/>
      <origin xyz="0 0 0"/>
      <inertia ixx="0.01" ixy="0.0" ixz="0.0" iyy="0.01" iyz="0.0" izz="0.01"/>
    </inertial>
    <visual>
      <origin rpy="0 0 0" xyz="0 0 0"/>
      <geometry>
        <mesh filename="package://rb1_arm_description/meshes/arms/armRB1_1_motor.dae"/>
      </geometry>
      <material name="darkgrey">
        <color rgba="0.1 0.1 0.1 1"/>
      </material>
    </visual>
    <collision>
      <origin rpy="0 0 0 " xyz="0 0 0"/>
      <geometry>
        <mesh filename="package://rb1_arm_description/meshes/arms/armRB1_1_motor.dae"/>
      </geometry>
    </collision>
  </link>
  <joint name="j1m_rb1_arm" type="fixed">
    <origin rpy="0.0 0.0 0.0" xyz="0.0 0.0 0.0"/>
    <parent link="link1_rb1_arm"/>
    <child link="motor1_rb1_arm"/>
    <axis xyz="0 0 0"/>
  </joint>
  <link name="link12_rb1_arm">
    <inertial>
      <mass value="0.5"/>
      <origin xyz="0 0 0"/>
      <inertia ixx="0.01" ixy="0.0" ixz="0.0" iyy="0.01" iyz="0.0" izz="0.01"/>
    </inertial>
    <visual>
      <origin rpy="0 0 0" xyz="0 0 0"/>
      <geometry>
        <mesh filename="package://rb1_arm_description/meshes/arms/armRB1_12_link.dae"/>
      </geometry>
      <material name="darkgrey">
        <color rgba="0.1 0.1 0.1 1"/>
      </material>
    </visual>
    <collision>
      <origin rpy="0 0 0 " xyz="0 0 0"/>
      <geometry>
        <mesh filename="package://rb1_arm_description/meshes/arms/armRB1_12_link.dae"/>
      </geometry>
    </collision>
  </link>
  <link name="motor12_rb1_arm">
    <inertial>
      <mass value="0.5"/>
      <origin xyz="0 0 0"/>
      <inertia ixx="0.01" ixy="0.0" ixz="0.0" iyy="0.01" iyz="0.0" izz="0.01"/>
    </inertial>
    <visual>
      <origin rpy="0 0 0" xyz="0 0 0"/>
      <geometry>
        <mesh filename="package://rb1_arm_description/meshes/arms/armRB1_12_motor.dae"/>
      </geometry>
      <material name="darkgrey">
        <color rgba="0.1 0.1 0.1 1"/>
      </material>
    </visual>
    <collision>
      <origin rpy="0 0 0 " xyz="0 0 0"/>
      <geometry>
        <mesh filename="package://rb1_arm_description/meshes/arms/armRB1_12_motor.dae"/>
      </geometry>
    </collision>
  </link>
  <joint name="j12m_rb1_arm" type="fixed">
    <origin rpy="0.0 0.0 0.0" xyz="0.0 0.0 0.0"/>
    <parent link="link12_rb1_arm"/>
    <child link="motor12_rb1_arm"/>
    <axis xyz="0 0 0"/>
  </joint>
  <link name="link23_rb1_arm">
    <inertial>
      <mass value="0.5"/>
      <origin xyz="0 0 0"/>
      <inertia ixx="0.01" ixy="0.0" ixz="0.0" iyy="0.01" iyz="0.0" izz="0.01"/>
    </inertial>
    <visual>
      <origin rpy="0 0 0" xyz="0 0 0"/>
      <geometry>
        <mesh filename="package://rb1_arm_description/meshes/arms/armRB1_23_link.dae"/>
      </geometry>
      <material name="darkgrey">
        <color rgba="0.1 0.1 0.1 1"/>
      </material>
    </visual>
    <collision>
      <origin rpy="0 0 0 " xyz="0 0 0"/>
      <geometry>
        <mesh filename="package://rb1_arm_description/meshes/arms/armRB1_23_link.dae"/>
      </geometry>
    </collision>
  </link>
  <link name="motor23_rb1_arm">
    <inertial>
      <mass value="0.5"/>
      <origin xyz="0 0 0"/>
      <inertia ixx="0.01" ixy="0.0" ixz="0.0" iyy="0.01" iyz="0.0" izz="0.01"/>
    </inertial>
    <visual>
      <origin rpy="0 0 0" xyz="0 0 0"/>
      <geometry>
        <mesh filename="package://rb1_arm_description/meshes/arms/armRB1_23_motor.dae"/>
      </geometry>
      <material name="darkgrey">
        <color rgba="0.1 0.1 0.1 1"/>
      </material>
    </visual>
    <collision>
      <origin rpy="0 0 0 " xyz="0 0 0"/>
      <geometry>
        <mesh filename="package://rb1_arm_description/meshes/arms/armRB1_23_motor.dae"/>
      </geometry>
    </collision>
  </link>
  <joint name="j23m_rb1_arm" type="fixed">
    <origin rpy="0.0 0.0 0.0" xyz="0.0 0.0 0.0"/>
    <parent link="link23_rb1_arm"/>
    <child link="motor23_rb1_arm"/>
    <axis xyz="0 0 0"/>
  </joint>
  <link name="link34_rb1_arm">
    <inertial>
      <mass value="0.5"/>
      <origin xyz="0 0 0"/>
      <inertia ixx="0.01" ixy="0.0" ixz="0.0" iyy="0.01" iyz="0.0" izz="0.01"/>
    </inertial>
    <visual>
      <origin rpy="0 0 0" xyz="0 0 0"/>
      <geometry>
        <mesh filename="package://rb1_arm_description/meshes/arms/armRB1_34_link.dae"/>
      </geometry>
      <material name="darkgrey">
        <color rgba="0.1 0.1 0.1 1"/>
      </material>
    </visual>
    <collision>
      <origin rpy="0 0 0 " xyz="0 0 0"/>
      <geometry>
        <mesh filename="package://rb1_arm_description/meshes/arms/armRB1_34_link.dae"/>
      </geometry>
    </collision>
  </link>
  <link name="motor34_rb1_arm">
    <inertial>
      <mass value="0.5"/>
      <origin xyz="0 0 0"/>
      <inertia ixx="0.01" ixy="0.0" ixz="0.0" iyy="0.01" iyz="0.0" izz="0.01"/>
    </inertial>
    <visual>
      <origin rpy="0 0 0" xyz="0 0 0"/>
      <geometry>
        <mesh filename="package://rb1_arm_description/meshes/arms/armRB1_34_motor.dae"/>
      </geometry>
      <material name="darkgrey">
        <color rgba="0.1 0.1 0.1 1"/>
      </material>
    </visual>
    <collision>
      <origin rpy="0 0 0 " xyz="0 0 0"/>
      <geometry>
        <mesh filename="package://rb1_arm_description/meshes/arms/armRB1_34_motor.dae"/>
      </geometry>
    </collision>
  </link>
  <joint name="j34m_rb1_arm" type="fixed">
    <origin rpy="0.0 0.0 0.0" xyz="0.0 0.0 0.0"/>
    <parent link="link34_rb1_arm"/>
    <child link="motor34_rb1_arm"/>
    <axis xyz="0 0 0"/>
  </joint>
  <link name="link45_rb1_arm">
    <inertial>
      <mass value="0.5"/>
      <origin xyz="0 0 0"/>
      <inertia ixx="0.01" ixy="0.0" ixz="0.0" iyy="0.01" iyz="0.0" izz="0.01"/>
    </inertial>
    <visual>
      <origin rpy="0 0 0" xyz="0 0 0"/>
      <geometry>
        <mesh filename="package://rb1_arm_description/meshes/arms/armRB1_45_link.dae"/>
      </geometry>
      <material name="darkgrey">
        <color rgba="0.1 0.1 0.1 1"/>
      </material>
    </visual>
    <collision>
      <origin rpy="0 0 0 " xyz="0 0 0"/>
      <geometry>
        <mesh filename="package://rb1_arm_description/meshes/arms/armRB1_45_link.dae"/>
      </geometry>
    </collision>
  </link>
  <link name="motor45_rb1_arm">
    <inertial>
      <mass value="0.5"/>
      <origin xyz="0 0 0"/>
      <inertia ixx="0.01" ixy="0.0" ixz="0.0" iyy="0.01" iyz="0.0" izz="0.01"/>
    </inertial>
    <visual>
      <origin rpy="0 0 0" xyz="0 0 0"/>
      <geometry>
        <mesh filename="package://rb1_arm_description/meshes/arms/armRB1_45_motor.dae"/>
      </geometry>
      <material name="darkgrey">
        <color rgba="0.1 0.1 0.1 1"/>
      </material>
    </visual>
    <collision>
      <origin rpy="0 0 0 " xyz="0 0 0"/>
      <geometry>
        <mesh filename="package://rb1_arm_description/meshes/arms/armRB1_45_motor.dae"/>
      </geometry>
    </collision>
  </link>
  <joint name="j45m_rb1_arm" type="fixed">
    <origin rpy="0.0 0.0 0.0" xyz="0.0 0.0 0.0"/>
    <parent link="link45_rb1_arm"/>
    <child link="motor45_rb1_arm"/>
    <axis xyz="0 0 0"/>
  </joint>
  <link name="link56_rb1_arm">
    <inertial>
      <mass value="0.5"/>
      <origin xyz="0 0 0"/>
      <inertia ixx="0.01" ixy="0.0" ixz="0.0" iyy="0.01" iyz="0.0" izz="0.01"/>
    </inertial>
    <visual>
      <origin rpy="0 0 0" xyz="0 0 0"/>
      <geometry>
        <mesh filename="package://rb1_arm_description/meshes/arms/armRB1_56_link.dae"/>
      </geometry>
      <material name="darkgrey">
        <color rgba="0.1 0.1 0.1 1"/>
      </material>
    </visual>
    <collision>
      <origin rpy="0 0 0 " xyz="0 0 0"/>
      <geometry>
        <mesh filename="package://rb1_arm_description/meshes/arms/armRB1_56_link.dae"/>
      </geometry>
    </collision>
  </link>
  <link name="motor56_rb1_arm">
    <inertial>
      <mass value="0.5"/>
      <origin xyz="0 0 0"/>
      <inertia ixx="0.01" ixy="0.0" ixz="0.0" iyy="0.01" iyz="0.0" izz="0.01"/>
    </inertial>
    <visual>
      <origin rpy="0 0 0" xyz="0 0 0"/>
      <geometry>
        <mesh filename="package://rb1_arm_description/meshes/arms/armRB1_56_motor.dae"/>
      </geometry>
      <material name="darkgrey">
        <color rgba="0.1 0.1 0.1 1"/>
      </material>
    </visual>
    <collision>
      <origin rpy="0 0 0 " xyz="0 0 0"/>
      <geometry>
        <mesh filename="package://rb1_arm_description/meshes/arms/armRB1_56_motor.dae"/>
      </geometry>
    </collision>
  </link>
  <joint name="j56m_rb1_arm" type="fixed">
    <origin rpy="0.0 0.0 0.0" xyz="0.0 0.0 0.0"/>
    <parent link="link56_rb1_arm"/>
    <child link="motor56_rb1_arm"/>
    <axis xyz="0 0 0"/>
  </joint>
  <link name="link67_rb1_arm">
    <inertial>
      <mass value="0.5"/>
      <origin xyz="0 0 0"/>
      <inertia ixx="0.01" ixy="0.0" ixz="0.0" iyy="0.01" iyz="0.0" izz="0.01"/>
    </inertial>
    <visual>
      <origin rpy="0 0 0" xyz="0 0 0"/>
      <geometry>
        <mesh filename="package://rb1_arm_description/meshes/arms/armRB1_67_link.dae"/>
      </geometry>
      <material name="darkgrey">
        <color rgba="0.1 0.1 0.1 1"/>
      </material>
    </visual>
    <collision>
      <origin rpy="0 0 0 " xyz="0 0 0"/>
      <geometry>
        <mesh filename="package://rb1_arm_description/meshes/arms/armRB1_67_link.dae"/>
      </geometry>
    </collision>
  </link>
  <link name="motor67_rb1_arm">
    <inertial>
      <mass value="0.5"/>
      <origin xyz="0 0 0"/>
      <inertia ixx="0.01" ixy="0.0" ixz="0.0" iyy="0.01" iyz="0.0" izz="0.01"/>
    </inertial>
    <visual>
      <origin rpy="0 0 0" xyz="0 0 0"/>
      <geometry>
        <mesh filename="package://rb1_arm_description/meshes/arms/armRB1_67_motor.dae"/>
      </geometry>
      <material name="darkgrey">
        <color rgba="0.1 0.1 0.1 1"/>
      </material>
    </visual>
    <collision>
      <origin rpy="0 0 0 " xyz="0 0 0"/>
      <geometry>
        <mesh filename="package://rb1_arm_description/meshes/arms/armRB1_67_motor.dae"/>
      </geometry>
    </collision>
  </link>
  <joint name="j67m_rb1_arm" type="fixed">
    <origin rpy="0.0 0.0 0.0" xyz="0.0 0.0 0.0"/>
    <parent link="link67_rb1_arm"/>
    <child link="motor67_rb1_arm"/>
    <axis xyz="0 0 0"/>
  </joint>
  <joint name="j1_rb1_arm" type="fixed">
    <origin rpy="0.0 0.0 0.0" xyz="0.0 0.0 0.0"/>
    <parent link="base_link_rb1_arm"/>
    <child link="link1_rb1_arm"/>
    <axis xyz="0 0 0"/>
  </joint>
  <joint name="j1" type="revolute">
    <origin rpy="0.0 0.0 0.0" xyz="0 0 0"/>
    <parent link="link1_rb1_arm"/>
    <child link="link12_rb1_arm"/>
    <axis xyz="0 0 -1"/>
    <limit effort="2500.0" lower="-1.57079632679" upper="1.57079632679" velocity="3.0"/>
    <dynamics damping="0.1" friction="0.1"/>
  </joint>
  <transmission name="j1_trans">
    <type>transmission_interface/SimpleTransmission</type>
    <joint name="j1"/>
    <actuator name="j1_motor">
      <hardwareInterface>EffortJointInterface</hardwareInterface>
      <mechanicalReduction>502.0</mechanicalReduction>
      <motorTorqueConstant>50.0</motorTorqueConstant>
    </actuator>
  </transmission>
  <joint name="j2" type="revolute">
    <origin rpy="1.57079632679 0.0 0.0" xyz="0.135 0 0"/>
    <parent link="link12_rb1_arm"/>
    <child link="link23_rb1_arm"/>
    <axis xyz="0 0 -1"/>
    <limit effort="2500.0" lower="-1.57079632679" upper="1.57079632679" velocity="3.0"/>
    <dynamics damping="0.1" friction="0.1"/>
  </joint>
  <transmission name="j2_trans">
    <type>transmission_interface/SimpleTransmission</type>
    <joint name="j2"/>
    <actuator name="j2_motor">
      <hardwareInterface>EffortJointInterface</hardwareInterface>
      <mechanicalReduction>502.0</mechanicalReduction>
      <motorTorqueConstant>50.0</motorTorqueConstant>
    </actuator>
  </transmission>
  <joint name="j3" type="revolute">
    <origin rpy="0.0 0.0 0.0" xyz="0.310 0 0"/>
    <parent link="link23_rb1_arm"/>
    <child link="link34_rb1_arm"/>
    <axis xyz="1 0 0"/>
    <limit effort="2500.0" lower="-3.14159265359" upper="3.14159265359" velocity="3.0"/>
    <dynamics damping="0.1" friction="0.1"/>
  </joint>
  <transmission name="j3_trans">
    <type>transmission_interface/SimpleTransmission</type>
    <joint name="j3"/>
    <actuator name="j3_motor">
      <hardwareInterface>EffortJointInterface</hardwareInterface>
      <mechanicalReduction>502.0</mechanicalReduction>
      <motorTorqueConstant>5.0</motorTorqueConstant>
    </actuator>
  </transmission>
  <joint name="j4" type="revolute">
    <origin rpy="0.0 0.0 0.0" xyz="0 0 0"/>
    <parent link="link34_rb1_arm"/>
    <child link="link45_rb1_arm"/>
    <axis xyz="0 0 -1"/>
    <limit effort="2500.0" lower="-2.0" upper="2.0" velocity="3.0"/>
    <dynamics damping="0.1" friction="0.1"/>
  </joint>
  <transmission name="j4_trans">
    <type>transmission_interface/SimpleTransmission</type>
    <joint name="j4"/>
    <actuator name="j4_motor">
      <hardwareInterface>EffortJointInterface</hardwareInterface>
      <mechanicalReduction>502.0</mechanicalReduction>
      <motorTorqueConstant>5.0</motorTorqueConstant>
    </actuator>
  </transmission>
  <joint name="j5" type="revolute">
    <origin rpy="0.0 0.0 0.0" xyz="0.285 0 0"/>
    <parent link="link45_rb1_arm"/>
    <child link="link56_rb1_arm"/>
    <axis xyz="1 0 0"/>
    <limit effort="2500.0" lower="-3.14159265359" upper="3.14159265359" velocity="3.0"/>
    <dynamics damping="0.1" friction="0.1"/>
  </joint>
  <transmission name="j5_trans">
    <type>transmission_interface/SimpleTransmission</type>
    <joint name="j5"/>
    <actuator name="j5_motor">
      <hardwareInterface>EffortJointInterface</hardwareInterface>
      <mechanicalReduction>502.0</mechanicalReduction>
      <motorTorqueConstant>5.0</motorTorqueConstant>
    </actuator>
  </transmission>
  <joint name="j6" type="revolute">
    <origin rpy="0.0 0.0 0.0" xyz="0 0 0"/>
    <parent link="link56_rb1_arm"/>
    <child link="link67_rb1_arm"/>
    <axis xyz="0 0 -1"/>
    <limit effort="2500.0" lower="-2.0" upper="2.0" velocity="3.0"/>
    <dynamics damping="0.1" friction="0.1"/>
  </joint>
  <transmission name="j6_trans">
    <type>transmission_interface/SimpleTransmission</type>
    <joint name="j6"/>
    <actuator name="j6_motor">
      <hardwareInterface>EffortJointInterface</hardwareInterface>
      <mechanicalReduction>304.0</mechanicalReduction>
      <motorTorqueConstant>3.0</motorTorqueConstant>
    </actuator>
  </transmission>
  <link name="end_effector_rb1_arm">
    <visual>
      <origin rpy="0 0 0" xyz="0 0 0.030"/>
      <geometry>
        <cylinder length="0.010" radius="0.015"/>
      </geometry>
    </visual>
    <collision>
      <origin rpy="0 0 0" xyz="0 0 0"/>
      <geometry>
        <cylinder length="0.005" radius="0.025"/>
      </geometry>
    </collision>
    <inertial>
      <origin rpy="0 0 0" xyz="0 0 0"/>
      <mass value="0.1"/>
      <inertia ixx="0.01" ixy="0.0" ixz="0.0" iyy="0.01" iyz="0.0" izz="0.01"/>
    </inertial>
  </link>
  <joint name="j7" type="revolute">
    <origin rpy="0.0 1.57079632679 0.0" xyz="0 0 0"/>
    <parent link="link67_rb1_arm"/>
    <child link="end_effector_rb1_arm"/>
    <axis xyz="0 0 -1"/>
    <limit effort="2500.0" lower="-3.14159265359" upper="3.14159265359" velocity="3.0"/>
    <dynamics damping="0.1" friction="0.1"/>
  </joint>
  <transmission name="j7_trans">
    <type>transmission_interface/SimpleTransmission</type>
    <joint name="j7"/>
    <actuator name="j7_motor">
      <hardwareInterface>EffortJointInterface</hardwareInterface>
      <mechanicalReduction>304.0</mechanicalReduction>
      <motorTorqueConstant>3.0</motorTorqueConstant>
    </actuator>
  </transmission>
  <gazebo>
    <plugin filename="libgazebo_ros_control.so" name="ros_control">
      <robotNamespace>/rb1_arm</robotNamespace>
      <!-- robotNamespace>/rb1</robotNamespace -->
      <robotParam>robot_description</robotParam>
      <controlPeriod>0.001</controlPeriod>
      <!-- controlPeriod>0.003</controlPeriod -->
      <robotSimType>gazebo_ros_control/DefaultRobotHWSim</robotSimType>
    </plugin>
  </gazebo>
  <!-- Gazebo ros control plugins -->
  <!-- xacro:ros_control/ -->
  <!-- Fix torso to base -->
  <joint name="j_base_torso" type="fixed">
    <origin rpy="0.0 0.0 0.0" xyz="0.0 0.0 0.0"/>
    <parent link="base_link"/>
    <child link="base_link_rb1_torso"/>
    <axis xyz="0 0 0"/>
  </joint>
  <!-- Fix arm to torso -->
  <joint name="j_torso_arm" type="fixed">
    <origin rpy="0.0 0.0 0.0" xyz="0.074 0.0 0.668"/>
    <parent link="link2_torso"/>
    <child link="base_link_rb1_arm"/>
    <axis xyz="0 0 0"/>
  </joint>
</robot>

